[2022-09-11T16:38:27.100+0000] {taskinstance.py:1171} INFO - Dependencies all met for <TaskInstance: scrapping_etl.etl manual__2022-09-11T16:33:22.560652+00:00 [queued]>
[2022-09-11T16:38:27.108+0000] {taskinstance.py:1171} INFO - Dependencies all met for <TaskInstance: scrapping_etl.etl manual__2022-09-11T16:33:22.560652+00:00 [queued]>
[2022-09-11T16:38:27.109+0000] {taskinstance.py:1368} INFO - 
--------------------------------------------------------------------------------
[2022-09-11T16:38:27.109+0000] {taskinstance.py:1369} INFO - Starting attempt 2 of 2
[2022-09-11T16:38:27.110+0000] {taskinstance.py:1370} INFO - 
--------------------------------------------------------------------------------
[2022-09-11T16:38:27.119+0000] {taskinstance.py:1389} INFO - Executing <Task(PythonOperator): etl> on 2022-09-11 16:33:22.560652+00:00
[2022-09-11T16:38:27.124+0000] {standard_task_runner.py:52} INFO - Started process 23362 to run task
[2022-09-11T16:38:27.127+0000] {standard_task_runner.py:79} INFO - Running: ['***', 'tasks', 'run', 'scrapping_etl', 'etl', 'manual__2022-09-11T16:33:22.560652+00:00', '--job-id', '14', '--raw', '--subdir', 'DAGS_FOLDER/job_dag.py', '--cfg-path', '/tmp/tmp0_ejbmwz', '--error-file', '/tmp/tmpf4n0ql71']
[2022-09-11T16:38:27.128+0000] {standard_task_runner.py:80} INFO - Job 14: Subtask etl
[2022-09-11T16:38:27.172+0000] {task_command.py:371} INFO - Running <TaskInstance: scrapping_etl.etl manual__2022-09-11T16:33:22.560652+00:00 [running]> on host 71464bd58847
[2022-09-11T16:38:27.212+0000] {taskinstance.py:1583} INFO - Exporting the following env vars:
AIRFLOW_CTX_DAG_EMAIL=c.mendozar@outlook.com
AIRFLOW_CTX_DAG_OWNER=***
AIRFLOW_CTX_DAG_ID=scrapping_etl
AIRFLOW_CTX_TASK_ID=etl
AIRFLOW_CTX_EXECUTION_DATE=2022-09-11T16:33:22.560652+00:00
AIRFLOW_CTX_TRY_NUMBER=2
AIRFLOW_CTX_DAG_RUN_ID=manual__2022-09-11T16:33:22.560652+00:00
[2022-09-11T16:38:29.536+0000] {logging_mixin.py:115} INFO - 2022-09-11
[2022-09-11T16:38:29.538+0000] {taskinstance.py:1902} ERROR - Task failed with exception
Traceback (most recent call last):
  File "/home/airflow/.local/lib/python3.7/site-packages/airflow/operators/python.py", line 171, in execute
    return_value = self.execute_callable()
  File "/home/airflow/.local/lib/python3.7/site-packages/airflow/operators/python.py", line 189, in execute_callable
    return self.python_callable(*self.op_args, **self.op_kwargs)
  File "/opt/airflow/dags/etl.py", line 18, in etl_jobs
    print('datetime:', datetime.datetime.strptime(day))
TypeError: strptime() takes exactly 2 arguments (1 given)
[2022-09-11T16:38:29.550+0000] {taskinstance.py:1412} INFO - Marking task as FAILED. dag_id=scrapping_etl, task_id=etl, execution_date=20220911T163322, start_date=20220911T163827, end_date=20220911T163829
[2022-09-11T16:38:29.559+0000] {warnings.py:110} WARNING - /home/***/.local/lib/python3.7/site-packages/***/utils/email.py:119: PendingDeprecationWarning: Fetching SMTP credentials from configuration variables will be deprecated in a future release. Please set credentials using a connection instead.
  send_mime_email(e_from=mail_from, e_to=recipients, mime_msg=msg, conn_id=conn_id, dryrun=dryrun)

[2022-09-11T16:38:29.560+0000] {configuration.py:562} WARNING - section/key [smtp/smtp_user] not found in config
[2022-09-11T16:38:29.560+0000] {email.py:228} INFO - Email alerting: attempt 1
[2022-09-11T16:38:29.566+0000] {configuration.py:562} WARNING - section/key [smtp/smtp_user] not found in config
[2022-09-11T16:38:29.567+0000] {email.py:228} INFO - Email alerting: attempt 1
[2022-09-11T16:38:29.568+0000] {taskinstance.py:1957} ERROR - Failed to send email to: ['c.mendozar@outlook.com']
Traceback (most recent call last):
  File "/home/airflow/.local/lib/python3.7/site-packages/airflow/models/taskinstance.py", line 1463, in _run_raw_task
    self._execute_task_with_callbacks(context, test_mode)
  File "/home/airflow/.local/lib/python3.7/site-packages/airflow/models/taskinstance.py", line 1610, in _execute_task_with_callbacks
    result = self._execute_task(context, task_orig)
  File "/home/airflow/.local/lib/python3.7/site-packages/airflow/models/taskinstance.py", line 1671, in _execute_task
    result = execute_callable(context=context)
  File "/home/airflow/.local/lib/python3.7/site-packages/airflow/operators/python.py", line 171, in execute
    return_value = self.execute_callable()
  File "/home/airflow/.local/lib/python3.7/site-packages/airflow/operators/python.py", line 189, in execute_callable
    return self.python_callable(*self.op_args, **self.op_kwargs)
  File "/opt/airflow/dags/etl.py", line 18, in etl_jobs
    print('datetime:', datetime.datetime.strptime(day))
TypeError: strptime() takes exactly 2 arguments (1 given)

During handling of the above exception, another exception occurred:

Traceback (most recent call last):
  File "/home/airflow/.local/lib/python3.7/site-packages/airflow/models/taskinstance.py", line 2339, in email_alert
    send_email(task.email, subject, html_content)
  File "/home/airflow/.local/lib/python3.7/site-packages/airflow/utils/email.py", line 71, in send_email
    **kwargs,
  File "/home/airflow/.local/lib/python3.7/site-packages/airflow/utils/email.py", line 119, in send_email_smtp
    send_mime_email(e_from=mail_from, e_to=recipients, mime_msg=msg, conn_id=conn_id, dryrun=dryrun)
  File "/home/airflow/.local/lib/python3.7/site-packages/airflow/utils/email.py", line 230, in send_mime_email
    smtp_conn = _get_smtp_connection(smtp_host, smtp_port, smtp_timeout, smtp_ssl)
  File "/home/airflow/.local/lib/python3.7/site-packages/airflow/utils/email.py", line 264, in _get_smtp_connection
    else smtplib.SMTP(host=host, port=port, timeout=timeout)
  File "/usr/local/lib/python3.7/smtplib.py", line 251, in __init__
    (code, msg) = self.connect(host, port)
  File "/usr/local/lib/python3.7/smtplib.py", line 336, in connect
    self.sock = self._get_socket(host, port, self.timeout)
  File "/usr/local/lib/python3.7/smtplib.py", line 307, in _get_socket
    self.source_address)
  File "/usr/local/lib/python3.7/socket.py", line 728, in create_connection
    raise err
  File "/usr/local/lib/python3.7/socket.py", line 716, in create_connection
    sock.connect(sa)
OSError: [Errno 99] Cannot assign requested address

During handling of the above exception, another exception occurred:

Traceback (most recent call last):
  File "/home/airflow/.local/lib/python3.7/site-packages/airflow/models/taskinstance.py", line 1955, in handle_failure
    self.email_alert(error, task)
  File "/home/airflow/.local/lib/python3.7/site-packages/airflow/models/taskinstance.py", line 2341, in email_alert
    send_email(task.email, subject, html_content_err)
  File "/home/airflow/.local/lib/python3.7/site-packages/airflow/utils/email.py", line 71, in send_email
    **kwargs,
  File "/home/airflow/.local/lib/python3.7/site-packages/airflow/utils/email.py", line 119, in send_email_smtp
    send_mime_email(e_from=mail_from, e_to=recipients, mime_msg=msg, conn_id=conn_id, dryrun=dryrun)
  File "/home/airflow/.local/lib/python3.7/site-packages/airflow/utils/email.py", line 230, in send_mime_email
    smtp_conn = _get_smtp_connection(smtp_host, smtp_port, smtp_timeout, smtp_ssl)
  File "/home/airflow/.local/lib/python3.7/site-packages/airflow/utils/email.py", line 264, in _get_smtp_connection
    else smtplib.SMTP(host=host, port=port, timeout=timeout)
  File "/usr/local/lib/python3.7/smtplib.py", line 251, in __init__
    (code, msg) = self.connect(host, port)
  File "/usr/local/lib/python3.7/smtplib.py", line 336, in connect
    self.sock = self._get_socket(host, port, self.timeout)
  File "/usr/local/lib/python3.7/smtplib.py", line 307, in _get_socket
    self.source_address)
  File "/usr/local/lib/python3.7/socket.py", line 728, in create_connection
    raise err
  File "/usr/local/lib/python3.7/socket.py", line 716, in create_connection
    sock.connect(sa)
OSError: [Errno 99] Cannot assign requested address
[2022-09-11T16:38:29.578+0000] {standard_task_runner.py:97} ERROR - Failed to execute job 14 for task etl (strptime() takes exactly 2 arguments (1 given); 23362)
[2022-09-11T16:38:29.633+0000] {local_task_job.py:156} INFO - Task exited with return code 1
[2022-09-11T16:38:29.660+0000] {local_task_job.py:279} INFO - 0 downstream tasks scheduled from follow-on schedule check
