[2022-09-11T16:33:23.443+0000] {taskinstance.py:1171} INFO - Dependencies all met for <TaskInstance: scrapping_etl.etl manual__2022-09-11T16:33:22.560652+00:00 [queued]>
[2022-09-11T16:33:23.450+0000] {taskinstance.py:1171} INFO - Dependencies all met for <TaskInstance: scrapping_etl.etl manual__2022-09-11T16:33:22.560652+00:00 [queued]>
[2022-09-11T16:33:23.452+0000] {taskinstance.py:1368} INFO - 
--------------------------------------------------------------------------------
[2022-09-11T16:33:23.453+0000] {taskinstance.py:1369} INFO - Starting attempt 1 of 2
[2022-09-11T16:33:23.454+0000] {taskinstance.py:1370} INFO - 
--------------------------------------------------------------------------------
[2022-09-11T16:33:23.462+0000] {taskinstance.py:1389} INFO - Executing <Task(PythonOperator): etl> on 2022-09-11 16:33:22.560652+00:00
[2022-09-11T16:33:23.468+0000] {standard_task_runner.py:52} INFO - Started process 23106 to run task
[2022-09-11T16:33:23.471+0000] {standard_task_runner.py:79} INFO - Running: ['***', 'tasks', 'run', 'scrapping_etl', 'etl', 'manual__2022-09-11T16:33:22.560652+00:00', '--job-id', '13', '--raw', '--subdir', 'DAGS_FOLDER/job_dag.py', '--cfg-path', '/tmp/tmpo8yy6w57', '--error-file', '/tmp/tmp6n56tpir']
[2022-09-11T16:33:23.474+0000] {standard_task_runner.py:80} INFO - Job 13: Subtask etl
[2022-09-11T16:33:23.534+0000] {task_command.py:371} INFO - Running <TaskInstance: scrapping_etl.etl manual__2022-09-11T16:33:22.560652+00:00 [running]> on host 71464bd58847
[2022-09-11T16:33:23.584+0000] {taskinstance.py:1583} INFO - Exporting the following env vars:
AIRFLOW_CTX_DAG_EMAIL=c.mendozar@outlook.com
AIRFLOW_CTX_DAG_OWNER=***
AIRFLOW_CTX_DAG_ID=scrapping_etl
AIRFLOW_CTX_TASK_ID=etl
AIRFLOW_CTX_EXECUTION_DATE=2022-09-11T16:33:22.560652+00:00
AIRFLOW_CTX_TRY_NUMBER=1
AIRFLOW_CTX_DAG_RUN_ID=manual__2022-09-11T16:33:22.560652+00:00
[2022-09-11T16:33:26.682+0000] {logging_mixin.py:115} INFO - 2022-09-11
[2022-09-11T16:33:26.686+0000] {taskinstance.py:1902} ERROR - Task failed with exception
Traceback (most recent call last):
  File "/home/airflow/.local/lib/python3.7/site-packages/airflow/operators/python.py", line 171, in execute
    return_value = self.execute_callable()
  File "/home/airflow/.local/lib/python3.7/site-packages/airflow/operators/python.py", line 189, in execute_callable
    return self.python_callable(*self.op_args, **self.op_kwargs)
  File "/opt/airflow/dags/etl.py", line 20, in etl_jobs
    print('datetime:', datetime.datetime.strptime(day))
TypeError: strptime() takes exactly 2 arguments (1 given)
[2022-09-11T16:33:26.698+0000] {taskinstance.py:1412} INFO - Marking task as UP_FOR_RETRY. dag_id=scrapping_etl, task_id=etl, execution_date=20220911T163322, start_date=20220911T163323, end_date=20220911T163326
[2022-09-11T16:33:26.714+0000] {standard_task_runner.py:97} ERROR - Failed to execute job 13 for task etl (strptime() takes exactly 2 arguments (1 given); 23106)
[2022-09-11T16:33:26.775+0000] {local_task_job.py:156} INFO - Task exited with return code 1
[2022-09-11T16:33:26.824+0000] {local_task_job.py:279} INFO - 0 downstream tasks scheduled from follow-on schedule check
